#include <vector>
#include <exception>
#include <iostream>
#include <execution>

using namespace std;
using namespace std::execution;

int main()
{
    vector<int> v{3,1,4,1,5,9};
    try
    {
        sort(seq, v.begin(), v.end(), 
             [](int a, int b){
                throw std::out_of_range("Oops"); 
                return true;
             });
    }
    catch(const std::exception& e)
    {
        std::cout << "Caught exception: " << e.what() <<std::endl;
    }
    
}